<?xml version="1.0" encoding="utf-8"?>
<!-- This URDF was automatically created by SolidWorks to URDF Exporter! Originally created by Stephen Brawner (brawner@gmail.com) 
     Commit Version: 1.6.0-1-g15f4949  Build Version: 1.6.7594.29634
     For more information, please see http://wiki.ros.org/sw_urdf_exporter -->
<robot
  name="thubot1">

  <!-- <link name="base_footprint"/>

  <joint name="base_joint" type="fixed">
    <parent link="base_footprint"/>
    <child link="base_link"/>
    <origin xyz="0.0 0.0 0.080" rpy="0 0 0"/>
  </joint> -->

  <!-- <link
    name="base_link">
    <inertial>
      <origin
        xyz="-0.0174205581189087 0.0118841867371313 0.154947000770574"
        rpy="0 0 0" />
      <mass
        value="42.467827585255" />
      <inertia
        ixx="0.379671525908869"
        ixy="-0.00215707368254018"
        ixz="-0.00562783500623309"
        iyy="0.714259639895206"
        iyz="-0.000208962218248609"
        izz="0.8499070652385" />
    </inertial>
    <visual>
      <origin
        xyz="0 0 0"
        rpy="0 0 0" />
      <geometry>
        <mesh
          filename="package://thubot1_description/meshes/visual/base_link.STL" />
      </geometry>
      <material
        name="">
        <color
          rgba="1 1 1 1" />
      </material>
    </visual>
    <collision>
      <origin
        xyz="0.25 -0.25 -0.06"
        rpy="1.5708 0 3.1415926" />
      <geometry>
        <mesh
          filename="package://thubot1_description/meshes/collision/base_link_collision.STL" />
      </geometry>
    </collision>
  </link>
  <link
    name="wheel_left_link">
    <inertial>
      <origin
        xyz="-0.00054928823116606 0.000105913900703788 -0.00599337263640198"
        rpy="0 0 0" />
      <mass
        value="0.0285277898819827" />
      <inertia
        ixx="6.59852199083716E-06"
        ixy="-6.00722207531335E-11"
        ixz="-1.28572342414589E-10"
        iyy="6.60082070729698E-06"
        iyz="4.18065938760799E-12"
        izz="1.27269366305604E-05" />
    </inertial>
    <visual>
      <origin
        xyz="0 0 0"
        rpy="0 0 0" />
      <geometry>
        <mesh
          filename="package://thubot1_description/meshes/visual/wheel_left_link.STL" />
      </geometry>
      <material
        name="">
        <color
          rgba="0.792156862745098 0.819607843137255 0.933333333333333 1" />
      </material>
    </visual>
    <collision>
      <origin
        xyz="0 0 0"
        rpy="0 0 0" />
      <geometry>
        <mesh
          filename="package://thubot1_description/meshes/collision/wheel_left_link.STL" />
      </geometry>
    </collision>
  </link>
  <joint
    name="wheel_left_joint"
    type="continuous">
    <origin
      xyz="0 0.261 0"
      rpy="-1.5708 0 0" />
    <parent
      link="base_link" />
    <child
      link="wheel_left_link" />
    <axis
      xyz="0 0 1" />
  </joint>
  <link
    name="wheel_right_link">
    <inertial>
      <origin
        xyz="0.000549288231166062 0.000105913900703788 0.00599337263640198"
        rpy="0 0 0" />
      <mass
        value="0.0285277898819827" />
      <inertia
        ixx="6.59852199083716E-06"
        ixy="6.00722207531355E-11"
        ixz="-1.28572342414597E-10"
        iyy="6.60082070729698E-06"
        iyz="-4.18065938760452E-12"
        izz="1.27269366305604E-05" />
    </inertial>
    <visual>
      <origin
        xyz="0 0 0"
        rpy="0 0 0" />
      <geometry>
        <mesh
          filename="package://thubot1_description/meshes/visual/wheel_right_link.STL" />
      </geometry>
      <material
        name="">
        <color
          rgba="0.792156862745098 0.819607843137255 0.933333333333333 1" />
      </material>
    </visual>
    <collision>
      <origin
        xyz="0 0 0"
        rpy="0 0 0" />
      <geometry>
        <mesh
          filename="package://thubot1_description/meshes/collision/wheel_right_link.STL" />
      </geometry>
    </collision>
  </link>
  <joint
    name="wheel_right_joint"
    type="continuous">
    <origin
      xyz="0 -0.261 0"
      rpy="-1.5708 0 0" />
    <parent
      link="base_link" />
    <child
      link="wheel_right_link" />
    <axis
      xyz="0 0 1" />
  </joint> -->

  <link name="iiwa7_link_0">
    <inertial>
      <origin
        xyz="-0.0174205581189087 0.0118841867371313 0.154947000770574" 
        rpy="0 0 0" />
      <mass
        value="2500.467827585255" />
      <inertia
        ixx="6000"
        ixy="-0.00215707368254018"
        ixz="-0.00562783500623309"
        iyy="6000"
        iyz="-0.000208962218248609"
        izz="0.8499070652385" />
    </inertial>
    <!-- 
      ixx="0.379671525908869"
      ixy="-0.00215707368254018"
      ixz="-0.00562783500623309"
      iyy="0.714259639895206"
      iyz="-0.000208962218248609"
      izz="0.8499070652385" />
    -->
    <visual>
      <origin
        xyz="0 0 0"
        rpy="-1.57 0 0" />
      <geometry>
        <mesh
          filename="package://thubot1_description/meshes/visual/base_link.STL" />
      </geometry>
      <material
        name="">
        <color
          rgba="1 1 1 1" />
      </material>
    </visual>
    <collision>
      <origin
        xyz="0.25 -0.25 -0.06"
        rpy="0.0 0 3.1415926" />
      <geometry>
        <mesh
          filename="package://thubot1_description/meshes/collision/base_link_collision.STL" />
      </geometry>
    </collision>
  </link>
  <link name="car_wheel_left_link">
    <inertial>
      <origin
        xyz="-0.00054928823116606 0.000105913900703788 -0.00599337263640198"
        rpy="0 0 0" />
      <mass
        value="0.0285277898819827" />
      <inertia
        ixx="6.59852199083716E-06"
        ixy="-6.00722207531335E-11"
        ixz="-1.28572342414589E-10"
        iyy="6.60082070729698E-06"
        iyz="4.18065938760799E-12"
        izz="1.27269366305604E-05" />
    </inertial>
    <visual>
      <origin
        xyz="0 0 0"
        rpy="-1.57 0 0" />
      <geometry>
        <mesh
          filename="package://thubot1_description/meshes/visual/wheel_left_link.STL" />
      </geometry>
      <material
        name="">
        <color
          rgba="0.792156862745098 0.819607843137255 0.933333333333333 1" />
      </material>
    </visual>
    <collision>
      <origin
        xyz="0 0 0"
        rpy="-1.57 0 0" />
      <geometry>
        <mesh
          filename="package://thubot1_description/meshes/collision/wheel_left_link.STL" />
      </geometry>
    </collision>
  </link>
  <joint name="car_wheel_left_joint" type="continuous">
    <parent link="iiwa7_link_0" />
    <child link="car_wheel_left_link" />
    <origin xyz="0 0.261 0" rpy="-1.5708 0 0" />
    <axis xyz="0 0 1" />
    <limit effort="40" velocity="2"/>
    <dynamics damping="5.5" friction="0.025"/>
  </joint>
  <link name="car_wheel_right_link">
    <inertial>
      <origin
        xyz="0.000549288231166062 0.000105913900703788 0.00599337263640198"
        rpy="0 0 0" />
      <mass
        value="0.0285277898819827" />
      <inertia
        ixx="6.59852199083716E-06"
        ixy="6.00722207531355E-11"
        ixz="-1.28572342414597E-10"
        iyy="6.60082070729698E-06"
        iyz="-4.18065938760452E-12"
        izz="1.27269366305604E-05" />
    </inertial>
    <visual>
      <origin
        xyz="0 0 0"
        rpy="-1.57 0 0" />
      <geometry>
        <mesh
          filename="package://thubot1_description/meshes/visual/wheel_right_link.STL" />
      </geometry>
      <material
        name="">
        <color
          rgba="0.792156862745098 0.819607843137255 0.933333333333333 1" />
      </material>
    </visual>
    <collision>
      <origin
        xyz="0 0 0"
        rpy="-1.57 0 0" />
      <geometry>
        <mesh
          filename="package://thubot1_description/meshes/collision/wheel_right_link.STL" />
      </geometry>
    </collision>
  </link>
  <joint name="car_wheel_right_joint" type="continuous">
    <parent link="iiwa7_link_0" />
    <child link="car_wheel_right_link" />
    <origin
      xyz="0 -0.261 0"
      rpy="-1.5708 0 0" />
    <axis xyz="0 0 1" />
    <limit effort="40" velocity="2"/>
    <dynamics damping="5.5" friction="0.025"/>
  </joint>






  
  <!-- <link
    name="imu_link">
    <inertial>
      <origin
        xyz="0.000792082858284526 1.38777878078145E-17 -0.012670204993692"
        rpy="0 0 1.5708" />
      <mass
        value="0.0468512388980384" />
      <inertia
        ixx="8.11807645296422E-06"
        ixy="-3.95404361424383E-21"
        ixz="-1.02754012116106E-08"
        iyy="1.1732532946275E-05"
        iyz="-4.70553831773323E-21"
        izz="1.50539519804819E-05" />
    </inertial>
    <visual>
      <origin
        xyz="0 0 0"
        rpy="0 0 1.5708" />
      <geometry>
        <mesh
          filename="package://thubot1_description/meshes/visual/imu_link.STL" />
      </geometry>
      <material
        name="">
        <color
          rgba="1 1 1 1" />
      </material>
    </visual>
    <collision>
      <origin
        xyz="0 0 0"
        rpy="0 0 1.5708" />
      <geometry>
        <mesh
          filename="package://thubot1_description/meshes/collision/imu_link.STL" />
      </geometry>
    </collision>
  </link>
  <joint
    name="imu_joint"
    type="fixed">
    <origin
      xyz="-0.132 0.001 0.257"
      rpy="0 0 -1.5708" />
    <parent
      link="base_link" />
    <child
      link="imu_link" />
    <axis
      xyz="0 0 0" />
  </joint>
  <link
    name="base_scan">
    <inertial>
      <origin
        xyz="-0.0792700269732225 -0.000502782516134966 -0.0221945303898931"
        rpy="0 0 3.1415926" />
      <mass
        value="0.000292612751414373" />
      <inertia
        ixx="4.92906410371702E-09"
        ixy="-1.77494869219624E-14"
        ixz="1.01452239690971E-10"
        iyy="2.40304678421701E-09"
        iyz="-2.22399477126053E-15"
        izz="5.79098388231232E-09" />
    </inertial>
    <visual>
      <origin
        xyz="0 0 0"
        rpy="0 0 3.1415926" />
      <geometry>
        <mesh
          filename="package://thubot1_description/meshes/visual/base_scan.STL" />
      </geometry>
      <material
        name="">
        <color
          rgba="0.498039215686275 0.498039215686275 0.498039215686275 1" />
      </material>
    </visual>
    <collision>
      <origin
        xyz="0 0 0"
        rpy="0 0 3.1415926" />
      <geometry>
        <mesh
          filename="package://thubot1_description/meshes/collision/base_scan.STL" />
      </geometry>
    </collision>
  </link>
  <joint
    name="scan_joint"
    type="fixed">
    <origin
      xyz="0.18 0 0.36849"
      rpy="0 0 -3.1415926" />
    <parent
      link="base_link" />
    <child
      link="base_scan" />
    <axis
      xyz="0 0 0" />
  </joint> -->

  <link
    name="shoulder_Link">
    <inertial>
      <origin
        xyz="0.00215579656064623 0.0675269492548249 0.000166380479814213"
        rpy="0 0 0" />
      <mass
        value="2.37326151468102" />
      <inertia
        ixx="0.00464437636424801"
        ixy="3.37752841443834E-06"
        ixz="-6.35167995342536E-06"
        iyy="0.00257740285163467"
        iyz="2.76302522141466E-07"
        izz="0.00472586337172682" />
    </inertial>
    <visual>
      <origin
        xyz="0 0 0"
        rpy="0 0 0" />
      <geometry>
        <mesh
          filename="package://thubot1_description/meshes/visual/shoulder_Link.DAE" />
      </geometry>
      <material
        name="">
        <color
          rgba="0.898039215686275 0.917647058823529 0.929411764705882 1" />
      </material>
    </visual>
    <collision>
      <origin
        xyz="0 0 0"
        rpy="0 0 0" />
      <geometry>
        <mesh
          filename="package://thubot1_description/meshes/collision/shoulder_Link.STL" />
      </geometry>
    </collision>
  </link>
  <joint
    name="j1"
    type="revolute">
    <!-- <origin
      xyz="0 0 0.414"
      rpy="1.5708 0 1.6475096" /> -->
    <origin
      xyz="0 0 0.414"
      rpy="1.5708 0 -3.8503" />
    <!-- <origin
      xyz="0 0 0.074"
      rpy="1.5708 0 0.076717" /> -->
    <parent
      link="iiwa7_link_0" />
    <child
      link="shoulder_Link" />
    <axis
      xyz="0 1 0" />
    <limit
      lower="-3.0543261"
      upper="3.0543261"
      effort="150"
      velocity="3.15" />
    <calibration
      rising="0"
      falling="0" />
    <dynamics
      damping="0"
      friction="0" />
    <safety_controller
      soft_upper_limit="3.0543261"
      soft_lower_limit="-3.0543261"
      k_position="100"
      k_velocity="40" />
  </joint>
  <link
    name="upperarm_Link">
    <inertial>
      <origin
        xyz="0.14052615364316 3.19832122998853E-06 -0.0673220294744213"
        rpy="0 0 0" />
      <mass
        value="5.20488445581566" />
      <inertia
        ixx="0.0100877805389267"
        ixy="-1.86156773781519E-06"
        ixz="7.99549951803734E-16"
        iyy="0.0114295275122961"
        iyz="-4.02196283458795E-16"
        izz="0.0071309461346971" />
    </inertial>
    <visual>
      <origin
        xyz="0 0 0.13"
        rpy="0 0 0" />
      <geometry>
        <mesh
          filename="package://thubot1_description/meshes/visual/upperarm_Link.DAE" />
      </geometry>
      <material
        name="">
        <color
          rgba="0.898039215686275 0.917647058823529 0.929411764705882 1" />
      </material>
    </visual>
    <collision>
      <origin
        xyz="0 0 0"
        rpy="0 0 0" />
      <geometry>
        <mesh
          filename="package://thubot1_description/meshes/collision/upperarm_Link.STL" />
      </geometry>
    </collision>
  </link>
  <joint
    name="j2"
    type="revolute">
    <origin
      xyz="0.048656 0.0652 0.0037401"
      rpy="3.141593 -1.647517 0" /> 
    <parent
      link="shoulder_Link" />
    <child
      link="upperarm_Link" />
    <axis
      xyz="0 0 1" />
    <limit
      lower="-4.6251"
      upper="1.4835"
      effort="150"
      velocity="3.15" />
    <calibration
      rising="0"
      falling="0" />
    <dynamics
      damping="0"
      friction="0" />
    <safety_controller
      soft_upper_limit="1.4835"
      soft_lower_limit="-4.6251"
      k_position="100"
      k_velocity="40" />
  </joint>
  <link
    name="forearm_Link">
    <inertial>
      <origin
        xyz="0.192635357876029 0.0487629311118559 -4.94516124512836E-06"
        rpy="0 0 0" />
      <mass
        value="2.36119902745376" />
      <inertia
        ixx="0.0035452659318639"
        ixy="-7.3938698701374E-05"
        ixz="7.22720216440109E-07"
        iyy="0.00303455488056437"
        iyz="-2.92335000076181E-07"
        izz="0.00417679573122483" />
    </inertial>
    <visual>
      <origin
        xyz="0 0.0025 0"
        rpy="0 0 0" />
      <geometry>
        <mesh
          filename="package://thubot1_description/meshes/visual/forearm_Link.DAE" />
      </geometry>
      <material
        name="">
        <color
          rgba="0.898039215686275 0.917647058823529 0.929411764705882 1" />
      </material>
    </visual>
    <collision>
      <origin
        xyz="0 0 0"
        rpy="0 0 0" />
      <geometry>
        <mesh
          filename="package://thubot1_description/meshes/collision/forearm_Link.STL" />
      </geometry>
    </collision>
  </link>
  <joint
    name="j3"
    type="revolute">
    <origin
      xyz="0.28 0 0"
      rpy="1.5708 0 0" />
    <parent
      link="upperarm_Link" />
    <child
      link="forearm_Link" />
    <axis
      xyz="0 1 0" />
    <limit
      lower="-2.8274"
      upper="2.8274"
      effort="150"
      velocity="3.15" />
    <calibration
      rising="0"
      falling="0" />
    <dynamics
      damping="0"
      friction="0" />
    <safety_controller
      soft_upper_limit="2.8274"
      soft_lower_limit="-2.8274"
      k_position="100"
      k_velocity="40" />
  </joint>
  <link
    name="wrist1_Link">
    <inertial>
      <origin
        xyz="-0.0454134679338634 0.00172297187615156 4.23850043613353E-07"
        rpy="0 0 0" />
      <mass
        value="1.74643097684016" />
      <inertia
        ixx="0.00262730745088668"
        ixy="1.0106539916888E-05"
        ixz="-3.62880005254338E-08"
        iyy="0.00158503705125863"
        iyz="1.43437921244792E-08"
        izz="0.00273363370089196" />
    </inertial>
    <visual>
      <origin
        xyz="0.106 0 0"
        rpy="0 0 0" />
      <geometry>
        <mesh
          filename="package://thubot1_description/meshes/visual/wrist1_Link.DAE" />
      </geometry>
      <material
        name="">
        <color
          rgba="0.898039215686275 0.917647058823529 0.929411764705882 1" />
      </material>
    </visual>
    <collision>
      <origin
        xyz="0 0 0"
        rpy="0 0 0" />
      <geometry>
        <mesh
          filename="package://thubot1_description/meshes/collision/wrist1_Link.STL" />
      </geometry>
    </collision>
  </link>
  <joint
    name="j4"
    type="revolute">
    <origin
      xyz="0.24001 -0.004399 0"
      rpy="1.5708 0 1.5708" />
    <parent
      link="forearm_Link" />
    <child
      link="wrist1_Link" />
    <axis
      xyz="1 0 0" />
    <limit
      lower="-4.6251"
      upper="1.4835"
      effort="28"
      velocity="3.2" />
    <calibration
      rising="0"
      falling="0" />
    <dynamics
      damping="0"
      friction="0" />
    <safety_controller
      soft_upper_limit="1.4835"
      soft_lower_limit="-4.6251"
      k_position="100"
      k_velocity="40" />
  </joint>
  <link
    name="wrist2_Link">
    <inertial>
      <origin
        xyz="-0.0454134586122821 0.00172297186091633 4.35135087973705E-07"
        rpy="0 0 0" />
      <mass
        value="1.74643097580082" />
      <inertia
        ixx="0.00262730745010995"
        ixy="1.01065424165879E-05"
        ixz="-3.62775265607763E-08"
        iyy="0.00158503704914344"
        iyz="1.44762939343378E-08"
        izz="0.00273363369934455" />
    </inertial>
    <visual>
      <origin
        xyz="0 0 0"
        rpy="0 0 0" />
      <geometry>
        <mesh
          filename="package://thubot1_description/meshes/visual/wrist2_Link.DAE" />
      </geometry>
      <material
        name="">
        <color
          rgba="0.898039215686275 0.917647058823529 0.929411764705882 1" />
      </material>
    </visual>
    <collision>
      <origin
        xyz="0 0 0"
        rpy="0 0 0" />
      <geometry>
        <mesh
          filename="package://thubot1_description/meshes/collision/wrist2_Link.STL" />
      </geometry>
    </collision>
  </link>
  <joint
    name="j5"
    type="revolute">
    <origin
      xyz="0.057 -0.15 0"
      rpy="3.141593 0 -1.5708" />
    <parent
      link="wrist1_Link" />
    <child
      link="wrist2_Link" />
    <axis
      xyz="1 0 0" />
    <limit
      lower="-3.0543"
      upper="3.0543"
      effort="28"
      velocity="3.2" />
    <calibration
      rising="0"
      falling="0" />
    <dynamics
      damping="0"
      friction="0" />
    <safety_controller
      soft_upper_limit="3.0543"
      soft_lower_limit="-3.0543"
      k_position="100"
      k_velocity="40" />
  </joint>
  <link
    name="wrist3_Link">
    <inertial>
      <origin
        xyz="-2.38767308875232E-05 0.0229240957730459 7.5877926720147E-05"
        rpy="0 0 0" />
      <mass
        value="1.05057803931133" />
      <inertia
        ixx="0.000555936779063335"
        ixy="5.09768154107326E-07"
        ixz="1.02477772503103E-06"
        iyy="0.000831680492730721"
        iyz="2.52800063915235E-08"
        izz="0.000554791835939161" />
    </inertial>
    <visual>
      <origin
        xyz="0 0 0"
        rpy="0 0 0" />
      <geometry>
        <mesh
          filename="package://thubot1_description/meshes/visual/wrist3_Link.DAE" />
      </geometry>
      <material
        name="">
        <color
          rgba="0.898039215686275 0.917647058823529 0.929411764705882 1" />
      </material>
    </visual>
    <collision>
      <origin
        xyz="0 0 0"
        rpy="0 0 0" />
      <geometry>
        <mesh
          filename="package://thubot1_description/meshes/collision/wrist3_Link.STL" />
      </geometry>
    </collision>
  </link>
  <joint
    name="j6"
    type="revolute">
    <origin
      xyz="-0.048801 -0.0532 0"
      rpy="3.1416 -0.5 0" />
    <parent
      link="wrist2_Link" />
    <child
      link="wrist3_Link" />
    <axis
      xyz="0 1 0" />
    <limit
      lower="-3.0543"
      upper="3.0543"
      effort="28"
      velocity="3.2" />
    <calibration
      rising="0"
      falling="0" />
    <dynamics
      damping="0"
      friction="0" />
    <safety_controller
      soft_upper_limit="3.0543"
      soft_lower_limit="-3.0543"
      k_position="100"
      k_velocity="40" />
  </joint>
  <!-- Removing this joint seems to help with some stability things -->
 
   <link name="part_studio_link">
    <inertial>
      <mass value="0.05"/>
      <origin rpy="0 0 0" xyz="0 0 0"/>
      <inertia ixx="1e-4" ixy="0" ixz="0" iyy="1e-4" iyz="0" izz="1e-4"/>
    </inertial>
    <visual>
      <origin rpy="0 0 0"/> <!--  1.5707 -->
      <geometry>
        <!-- <mesh filename="package://franka_description/meshes/visual/Part Studio 1.obj"/> -->
        <!-- <mesh filename="package://franka_description/meshes/visual/mount_v6.stl" scale="0.001 0.001 0.001"/> -->
        <mesh filename="kuka_allegro_description/meshes/mounts/allegro_mount.obj"/>     
      </geometry>
    </visual>
    <collision>
      <origin rpy="0 0 0"/>
      <geometry>
        <!-- <mesh filename="package://franka_description/meshes/collision/Part Studio 1.obj"/> -->
        <!-- <mesh filename="package://franka_description/meshes/collision/mount_v6.stl" scale="0.001 0.001 0.001"/> -->
        <mesh filename="kuka_allegro_description/meshes/mounts/allegro_mount.obj"/>
      </geometry>
    
        
    </collision>
  </link>

  <joint name="part_studio_joint" type="fixed">
    <!--
    <parent link="panda_link8"/>
    -->
    <parent link="wrist3_Link"/>
    <child link="part_studio_link"/>
    <!-- <origin rpy="0 0 1.571" xyz="-0.02 0.0 0.107"/> -->
    
    <origin rpy="0 0 0" xyz="0 0 0"/>
   
  </joint>

  <!-- <link name="camera_link">
    <inertial>
      <mass value="0.05"/>
      <origin rpy="0 0 0" xyz="0 0 0"/>
      <inertia ixx="1e-4" ixy="0" ixz="0" iyy="1e-4" iyz="0" izz="1e-4"/>
    </inertial>
    <visual>
      <origin rpy="-1.571 0 0"/>
      <geometry>
        <mesh filename="C:\Users\xiaodu\Desktop\urdf_all\franka_panda_allegro/meshes/visual/realsense-d405.stl" scale="0.001 0.001 0.001"/>
      </geometry>
    </visual>
    <collision>
      <origin rpy="-1.571 0 0"/>
      <geometry>
        <mesh filename="C:\Users\xiaodu\Desktop\urdf_all\franka_panda_allegro/meshes/collision/realsense-d405.stl" scale="0.001 0.001 0.001"/>
      </geometry>
    
        
    </collision>
  </link>

  <joint name="camera_joint" type="fixed">
    <parent link="part_studio_link"/>
    <child link="camera_link"/>
    <origin rpy="-0.5 0 3.141592" xyz="-0.03 -0.05 0.055"/>
  </joint> -->



  <joint name="panda_hand_joint" type="fixed">
    <!--
    <parent link="panda_link8"/>
    -->
    <parent link="part_studio_link"/>
    <child link="R_hand_base_link"/>
    <origin rpy="-1.57 1.57 1.57" xyz="0.0 0.05 0.0"/>
    <!-- <origin rpy="0 0 -0.785398163397" xyz="0 0 0"/> -->
  </joint>

    <link name="R_hand_base_link">
    <inertial>
      <origin
        xyz="-0.0025264 -0.066047 0.0019598"
        rpy="0 0 0" />
      <mass
        value="0.14143" />
      <inertia
        ixx="0.00012281"
        ixy="2.1711E-06"
        ixz="1.7709E-06"
        iyy="8.3832E-05"
        iyz="-1.6551E-06"
        izz="7.6663E-05" />
    </inertial>
    <visual>
      <origin
        xyz="0 0 0"
        rpy="0 0 0" />
      <geometry>
        <mesh filename="./inspire_hand/meshes/R_hand_base_link.STL" />
      </geometry>
      <material name="">
        <color rgba="0.1 0.1 0.1 1" />
      </material>
    </visual>
    <collision>
      <origin
        xyz="0 0 0"
        rpy="0 0 0" />
      <geometry>
        <mesh filename="./inspire_hand/meshes/R_hand_base_link.STL" />
      </geometry>
    </collision>
  </link>

  <link name="R_thumb_proximal_base">
    <inertial>
      <origin
        xyz="-0.0048064 0.0009382 -0.00757"
        rpy="0 0 0" />
      <mass
        value="0.0018869" />
      <inertia
        ixx="5.816E-08"
        ixy="1.4539E-08"
        ixz="4.491E-09"
        iyy="7.9161E-08"
        iyz="-1.8727E-09"
        izz="6.7433E-08" />
    </inertial>
    <visual>
      <origin
        xyz="0 0 0"
        rpy="0 0 0" />
      <geometry>
        <mesh filename="./inspire_hand/meshes/Link11_R.STL" />
      </geometry>
      <material name="">
        <color rgba="0.1 0.1 0.1 1" />
      </material>
    </visual>
    <collision>
      <origin
        xyz="0 0 0"
        rpy="0 0 0" />
      <geometry>
        <mesh filename="./inspire_hand/meshes/Link11_R.STL" />
      </geometry>
    </collision>
  </link>

  <joint
    name="R_thumb_proximal_yaw_joint"
    type="revolute">
    <origin
      xyz="-0.01696 -0.0691 -0.02045"
      rpy="1.5708 -1.5708 0" />
    <parent
      link="R_hand_base_link" />
    <child
      link="R_thumb_proximal_base" />
    <axis
      xyz="0 0 -1" />
    <limit
      lower="-0.1"
      upper="1.3"
      effort="1"
      velocity="0.5" />
  </joint>

  <link name="R_thumb_proximal">
    <inertial>
      <origin
        xyz="0.021932 0.012785 -0.0080386"
        rpy="0 0 0" />
      <mass
        value="0.0066075" />
      <inertia
        ixx="1.5686E-06"
        ixy="-7.8296E-07"
        ixz="8.9143E-10"
        iyy="1.7353E-06"
        iyz="-1.0191E-09"
        izz="2.786E-06" />
    </inertial>
    <visual>
      <origin
        xyz="0 0 0"
        rpy="0 0 0" />
      <geometry>
        <mesh filename="./inspire_hand/meshes/Link12_R.STL" />
      </geometry>
      <material name="">
        <color rgba="0.1 0.1 0.1 1" />
      </material>
    </visual>
    <collision>
      <origin
        xyz="0 0 0"
        rpy="0 0 0" />
      <geometry>
        <mesh filename="./inspire_hand/meshes/Link12_R.STL" />
      </geometry>
    </collision>
  </link>

  <joint
    name="R_thumb_proximal_pitch_joint"
    type="revolute">
    <origin
      xyz="-0.0088099 0.010892 -0.00925"
      rpy="1.5708 0 2.8587" />
    <parent
      link="R_thumb_proximal_base" />
    <child
      link="R_thumb_proximal" />
    <axis
      xyz="0 0 1" />
    <limit
      lower="0.0"
      upper="0.5"
      effort="1"
      velocity="0.5" />
  </joint>

  <link name="R_thumb_intermediate">
    <inertial>
      <origin
        xyz="0.0095544 -0.0016282 -0.0071997"
        rpy="0 0 0" />
      <mass
        value="0.0037847" />
      <inertia
        ixx="3.6981E-07"
        ixy="-9.8581E-08"
        ixz="-4.7469E-12"
        iyy="3.2394E-07"
        iyz="1.0939E-12"
        izz="4.6531E-07" />
    </inertial>
    <visual>
      <origin
        xyz="0 0 0"
        rpy="0 0 0" />
      <geometry>
        <mesh filename="./inspire_hand/meshes/Link13_R.STL" />
      </geometry>
      <material name="">
        <color rgba="0.1 0.1 0.1 1" />
      </material>
    </visual>
    <collision>
      <origin
        xyz="0 0 0"
        rpy="0 0 0" />
      <geometry>
        <mesh filename="./inspire_hand/meshes/Link13_R.STL" />
      </geometry>
    </collision>
  </link>

  <joint
    name="R_thumb_intermediate_joint"
    type="revolute">
    <origin
      xyz="0.04407 0.034553 -0.0008"
      rpy="0 0 0" />
    <parent
      link="R_thumb_proximal" />
    <child
      link="R_thumb_intermediate" />
    <axis
      xyz="0 0 1" />
    <limit
      lower="0"
      upper="0.8"
      effort="1"
      velocity="0.5" />
    <mimic 
      joint="R_thumb_proximal_pitch_joint"
      multiplier="1.6"
      offset="0" />
  </joint>

  <link name="R_thumb_distal">
    <inertial>
      <origin
        xyz="0.0092888 0.0049529 -0.0060033"
        rpy="0 0 0" />
      <mass
        value="0.0033441" />
      <inertia
        ixx="1.3632E-07"
        ixy="-5.6788E-08"
        ixz="-9.2764E-11"
        iyy="1.4052E-07"
        iyz="-1.2283E-10"
        izz="2.0026E-07" />
    </inertial>
    <visual>
      <origin
        xyz="0 0 0"
        rpy="0 0 0" />
      <geometry>
        <mesh filename="./inspire_hand/meshes/Link14_R.STL" />
      </geometry>
      <material name="">
        <color rgba="0.1 0.1 0.1 1" />
      </material>
    </visual>
    <collision>
      <origin
        xyz="0 0 0"
        rpy="0 0 0" />
      <geometry>
        <mesh filename="./inspire_hand/meshes/Link14_R.STL" />
      </geometry>
    </collision>
  </link>

  <joint
    name="R_thumb_distal_joint"
    type="revolute">
    <origin
      xyz="0.020248 0.010156 -0.0012"
      rpy="0 0 0" />
    <parent
      link="R_thumb_intermediate" />
    <child
      link="R_thumb_distal" />
    <axis
      xyz="0 0 1" />
    <limit
      lower="0"
      upper="1.2"
      effort="1"
      velocity="0.5" />
    <mimic 
      joint="R_thumb_proximal_pitch_joint"
      multiplier="2.4"
      offset="0" />
  </joint>

  <link name="R_thumb_tip">
    <visual>
      <origin
        xyz="0 0 0"
        rpy="0 0 0" />
      <geometry>
        <sphere radius="0.005"/>
      </geometry>
      <material name="green">
        <color rgba="0 1 0 1" />
      </material>
    </visual>
  </link>
  <joint name="R_thumb_tip_joint" type="fixed">
    <parent link="R_thumb_distal"/>
    <child link="R_thumb_tip"/>
    <origin rpy="0 0 0" xyz="0.015 0.013 -0.004"/>
  </joint>

  <link name="R_index_proximal">
    <inertial>
      <origin
        xyz="0.0012259 0.011942 -0.0060001"
        rpy="0 0 0" />
      <mass
        value="0.0042403" />
      <inertia
        ixx="6.6232E-07"
        ixy="-1.5775E-08"
        ixz="1.8515E-12"
        iyy="2.1146E-07"
        iyz="-5.0828E-12"
        izz="6.9398E-07" />
    </inertial>
    <visual>
      <origin
        xyz="0 0 0"
        rpy="0 0 0" />
      <geometry>
        <mesh filename="./inspire_hand/meshes/Link15_R.STL" />
      </geometry>
      <material name="">
        <color rgba="0.1 0.1 0.1 1" />
      </material>
    </visual>
    <collision>
      <origin
        xyz="0 0 0"
        rpy="0 0 0" />
      <geometry>
        <mesh filename="./inspire_hand/meshes/Link15_R.STL" />
      </geometry>
    </collision>
  </link>

  <joint
    name="R_index_proximal_joint"
    type="revolute">
    <origin
      xyz="0.00028533 -0.13653 -0.032268"
      rpy="-3.1067 0 0" />
    <parent
      link="R_hand_base_link" />
    <child
      link="R_index_proximal" />
    <axis
      xyz="0 0 1" />
    <limit
      lower="0"
      upper="1.7"
      effort="1"
      velocity="0.5" />
  </joint>

  <link name="R_index_intermediate">
    <inertial>
      <origin
        xyz="0.0019697 0.019589 -0.005"
        rpy="0 0 0" />
      <mass
        value="0.0045683" />
      <inertia
        ixx="7.6111E-07"
        ixy="8.7637E-08"
        ixz="-3.7751E-13"
        iyy="9.6076E-08"
        iyz="9.9444E-13"
        izz="7.8179E-07" />
    </inertial>
    <visual>
      <origin
        xyz="0 0 0"
        rpy="0 0 0" />
      <geometry>
        <mesh filename="./inspire_hand/meshes/Link16_R.STL" />
      </geometry>
      <material name="">
        <color rgba="0.1 0.1 0.1 1" />
      </material>
    </visual>
    <collision>
      <origin
        xyz="0 0 0"
        rpy="0 0 0" />
      <geometry>
        <mesh filename="./inspire_hand/meshes/Link16_R.STL" />
      </geometry>
    </collision>
  </link>

  <joint
    name="R_index_intermediate_joint"
    type="revolute">
    <origin
      xyz="-0.0026138 0.032026 -0.001"
      rpy="0 0 0" />
    <parent
      link="R_index_proximal" />
    <child
      link="R_index_intermediate" />
    <axis
      xyz="0 0 1" />
    <limit
      lower="0"
      upper="1.7"
      effort="1"
      velocity="0.5" />
    <mimic 
      joint="R_index_proximal_joint"
      multiplier="1"
      offset="0" />
  </joint>

  <link name="R_index_tip">
    <visual>
      <origin
        xyz="0 0 0"
        rpy="0 0 0" />
      <geometry>
        <sphere radius="0.005"/>
      </geometry>
      <material name="green">
        <color rgba="0 1 0 1" />
      </material>
    </visual>
  </link>
  <joint name="R_index_tip_joint" type="fixed">
    <parent link="R_index_intermediate"/>
    <child link="R_index_tip"/>
    <origin rpy="0 0 0" xyz="-0.005 0.04 -0.004"/>
  </joint>

  <link name="R_middle_proximal">
    <inertial>
      <origin
        xyz="0.001297 0.011934 -0.0060001"
        rpy="0 0 0" />
      <mass
        value="0.0042403" />
      <inertia
        ixx="6.6211E-07"
        ixy="-1.8461E-08"
        ixz="1.8002E-12"
        iyy="2.1167E-07"
        iyz="-6.6808E-12"
        izz="6.9397E-07" />
    </inertial>
    <visual>
      <origin
        xyz="0 0 0"
        rpy="0 0 0" />
      <geometry>
        <mesh filename="./inspire_hand/meshes/Link17_R.STL" />
      </geometry>
      <material name="">
        <color rgba="0.1 0.1 0.1 1" />
      </material>
    </visual>
    <collision>
      <origin
        xyz="0 0 0"
        rpy="0 0 0" />
      <geometry>
        <mesh filename="./inspire_hand/meshes/Link17_R.STL" />
      </geometry>
    </collision>
  </link>

  <joint
    name="R_middle_proximal_joint"
    type="revolute">
    <origin
      xyz="0.00028533 -0.1371 -0.01295"
      rpy="-3.1416 0 0" />
    <parent
      link="R_hand_base_link" />
    <child
      link="R_middle_proximal" />
    <axis
      xyz="0 0 1" />
    <limit
      lower="0"
      upper="1.7"
      effort="1"
      velocity="0.5" />
  </joint>

  <link name="R_middle_intermediate">
    <inertial>
      <origin
        xyz="0.001921 0.020796 -0.005"
        rpy="0 0 0" />
      <mass
        value="0.0050396" />
      <inertia
        ixx="9.5822E-07"
        ixy="1.1425E-07"
        ixz="-2.4791E-12"
        iyy="1.0646E-07"
        iyz="5.9173E-12"
        izz="9.8384E-07" />
    </inertial>
    <visual>
      <origin
        xyz="0 0 0"
        rpy="0 0 0" />
      <geometry>
        <mesh filename="./inspire_hand/meshes/Link18_R.STL" />
      </geometry>
      <material name="">
        <color rgba="0.1 0.1 0.1 1" />
      </material>
    </visual>
    <collision>
      <origin
        xyz="0 0 0"
        rpy="0 0 0" />
      <geometry>
        <mesh filename="./inspire_hand/meshes/Link18_R.STL" />
      </geometry>
    </collision>
  </link>

  <joint
    name="R_middle_intermediate_joint"
    type="revolute">
    <origin
      xyz="-0.0024229 0.032041 -0.001"
      rpy="0 0 0" />
    <parent
      link="R_middle_proximal" />
    <child
      link="R_middle_intermediate" />
    <axis
      xyz="0 0 1" />
    <limit
      lower="0"
      upper="1.7"
      effort="1"
      velocity="0.5" />
    <mimic 
      joint="R_middle_proximal_joint"
      multiplier="1"
      offset="0" />
  </joint>

  <link name="R_middle_tip">
    <visual>
      <origin
        xyz="0 0 0"
        rpy="0 0 0" />
      <geometry>
        <sphere radius="0.005"/>
      </geometry>
      <material name="green">
        <color rgba="0 1 0 1" />
      </material>
    </visual>
  </link>
  <joint name="R_middle_tip_joint" type="fixed">
    <parent link="R_middle_intermediate"/>
    <child link="R_middle_tip"/>
    <origin rpy="0 0 0" xyz="-0.005 0.045 -0.004"/>
  </joint>

  <link name="R_ring_proximal">
    <inertial>
      <origin
        xyz="0.001297 0.011934 -0.0060002"
        rpy="0 0 0" />
      <mass
        value="0.0042403" />
      <inertia
        ixx="6.6211E-07"
        ixy="-1.8461E-08"
        ixz="1.5793E-12"
        iyy="2.1167E-07"
        iyz="-6.6868E-12"
        izz="6.9397E-07" />
    </inertial>
    <visual>
      <origin
        xyz="0 0 0"
        rpy="0 0 0" />
      <geometry>
        <mesh filename="./inspire_hand/meshes/Link19_R.STL" />
      </geometry>
      <material name="">
        <color rgba="0.1 0.1 0.1 1" />
      </material>
    </visual>
    <collision>
      <origin
        xyz="0 0 0"
        rpy="0 0 0" />
      <geometry>
        <mesh filename="./inspire_hand/meshes/Link19_R.STL" />
      </geometry>
    </collision>
  </link>

  <joint
    name="R_ring_proximal_joint"
    type="revolute">
    <origin
      xyz="0.00028533 -0.13691 0.0062872"
      rpy="3.0892 0 0" />
    <parent
      link="R_hand_base_link" />
    <child
      link="R_ring_proximal" />
    <axis
      xyz="0 0 1" />
    <limit
      lower="0"
      upper="1.7"
      effort="1"
      velocity="0.5" />
  </joint>

  <link name="R_ring_intermediate">
    <inertial>
      <origin
        xyz="0.0021753 0.019567 -0.005"
        rpy="0 0 0" />
      <mass
        value="0.0045683" />
      <inertia
        ixx="7.6286E-07"
        ixy="8.0635E-08"
        ixz="-6.1562E-13"
        iyy="9.431E-08"
        iyz="5.8619E-13"
        izz="7.8177E-07" />
    </inertial>
    <visual>
      <origin
        xyz="0 0 0"
        rpy="0 0 0" />
      <geometry>
        <mesh filename="./inspire_hand/meshes/Link20_R.STL" />
      </geometry>
      <material name="">
        <color rgba="0.1 0.1 0.1 1" />
      </material>
    </visual>
    <collision>
      <origin
        xyz="0 0 0"
        rpy="0 0 0" />
      <geometry>
        <mesh filename="./inspire_hand/meshes/Link20_R.STL" />
      </geometry>
    </collision>
  </link>

  <joint
    name="R_ring_intermediate_joint"
    type="revolute">
    <origin
      xyz="-0.0024229 0.032041 -0.001"
      rpy="0 0 0" />
    <parent
      link="R_ring_proximal" />
    <child
      link="R_ring_intermediate" />
    <axis
      xyz="0 0 1" />
    <limit
      lower="0"
      upper="1.7"
      effort="1"
      velocity="0.5" />
    <mimic 
      joint="R_ring_proximal_joint"
      multiplier="1"
      offset="0" />
  </joint>

  <link name="R_ring_tip">
    <visual>
      <origin
        xyz="0 0 0"
        rpy="0 0 0" />
      <geometry>
        <sphere radius="0.005"/>
      </geometry>
      <material name="green">
        <color rgba="0 1 0 1" />
      </material>
    </visual>
  </link>
  <joint name="R_ring_tip_joint" type="fixed">
    <parent link="R_ring_intermediate"/>
    <child link="R_ring_tip"/>
    <origin rpy="0 0 0" xyz="-0.002 0.04 -0.004"/>
  </joint>

  <link name="R_pinky_proximal">
    <inertial>
      <origin
        xyz="0.001297 0.011934 -0.0060001"
        rpy="0 0 0" />
      <mass
        value="0.0042403" />
      <inertia
        ixx="6.6211E-07"
        ixy="-1.8461E-08"
        ixz="1.6907E-12"
        iyy="2.1167E-07"
        iyz="-6.9334E-12"
        izz="6.9397E-07" />
    </inertial>
    <visual>
      <origin
        xyz="0 0 0"
        rpy="0 0 0" />
      <geometry>
        <mesh filename="./inspire_hand/meshes/Link21_R.STL" />
      </geometry>
      <material name="">
        <color rgba="0.1 0.1 0.1 1" />
      </material>
    </visual>
    <collision>
      <origin
        xyz="0 0 0"
        rpy="0 0 0" />
      <geometry>
        <mesh filename="./inspire_hand/meshes/Link21_R.STL" />
      </geometry>
    </collision>
  </link>

  <joint
    name="R_pinky_proximal_joint"
    type="revolute">
    <origin
      xyz="0.00028533 -0.13571 0.025488"
      rpy="3.0369 0 0" />
    <parent
      link="R_hand_base_link" />
    <child
      link="R_pinky_proximal" />
    <axis
      xyz="0 0 1" />
    <limit
      lower="0"
      upper="1.7"
      effort="1"
      velocity="0.5" />
  </joint>

  <link name="R_pinky_intermediate">
    <inertial>
      <origin
        xyz="0.0024748 0.016203 -0.0050031"
        rpy="0 0 0" />
      <mass
        value="0.0035996" />
      <inertia
        ixx="4.3913E-07"
        ixy="4.1418E-08"
        ixz="3.7168E-11"
        iyy="7.0247E-08"
        iyz="5.8613E-11"
        izz="4.4867E-07" />
    </inertial>
    <visual>
      <origin
        xyz="0 0 0"
        rpy="0 0 0" />
      <geometry>
        <mesh filename="./inspire_hand/meshes/Link22_R.STL" />
      </geometry>
      <material name="">
        <color rgba="0.1 0.1 0.1 1" />
      </material>
    </visual>
    <collision>
      <origin
        xyz="0 0 0"
        rpy="0 0 0" />
      <geometry>
        <mesh filename="./inspire_hand/meshes/Link22_R.STL" />
      </geometry>
    </collision>
  </link>

  <joint
    name="R_pinky_intermediate_joint"
    type="revolute">
    <origin
      xyz="-0.0024229 0.032041 -0.001"
      rpy="0 0 0" />
    <parent
      link="R_pinky_proximal" />
    <child
      link="R_pinky_intermediate" />
    <axis
      xyz="0 0 1" />
    <limit
      lower="0"
      upper="1.7"
      effort="1"
      velocity="0.5" />
    <mimic 
      joint="R_pinky_proximal_joint"
      multiplier="1"
      offset="0" />
  </joint>

  <link name="R_pinky_tip">
    <visual>
      <origin
        xyz="0 0 0"
        rpy="0 0 0" />
      <geometry>
        <sphere radius="0.005"/>
      </geometry>
      <material name="green">
        <color rgba="0 1 0 1" />
      </material>
    </visual>
  </link>
  <joint name="R_pinky_tip_joint" type="fixed">
    <parent link="R_pinky_intermediate"/>
    <child link="R_pinky_tip"/>
    <origin rpy="0 0 0" xyz="-0.002 0.032 -0.004"/>
  </joint>


</robot>

