<?xml version="1.0" encoding="utf-8"?>
<!-- This URDF was automatically created by SolidWorks to URDF Exporter! Originally created by Stephen Brawner (brawner@gmail.com) 
     Commit Version: 1.6.0-1-g15f4949  Build Version: 1.6.7594.29634
     For more information, please see http://wiki.ros.org/sw_urdf_exporter -->
<robot
  name="thubot1">

  <!-- <link name="base_footprint"/>

  <joint name="base_joint" type="fixed">
    <parent link="base_footprint"/>
    <child link="base_link"/>
    <origin xyz="0.0 0.0 0.080" rpy="0 0 0"/>
  </joint> -->

  <!-- <link
    name="base_link">
    <inertial>
      <origin
        xyz="-0.0174205581189087 0.0118841867371313 0.154947000770574"
        rpy="0 0 0" />
      <mass
        value="42.467827585255" />
      <inertia
        ixx="0.379671525908869"
        ixy="-0.00215707368254018"
        ixz="-0.00562783500623309"
        iyy="0.714259639895206"
        iyz="-0.000208962218248609"
        izz="0.8499070652385" />
    </inertial>
    <visual>
      <origin
        xyz="0 0 0"
        rpy="0 0 0" />
      <geometry>
        <mesh
          filename="package://thubot1_description/meshes/visual/base_link.STL" />
      </geometry>
      <material
        name="">
        <color
          rgba="1 1 1 1" />
      </material>
    </visual>
    <collision>
      <origin
        xyz="0.25 -0.25 -0.06"
        rpy="1.5708 0 3.1415926" />
      <geometry>
        <mesh
          filename="package://thubot1_description/meshes/collision/base_link_collision.STL" />
      </geometry>
    </collision>
  </link>
  <link
    name="wheel_left_link">
    <inertial>
      <origin
        xyz="-0.00054928823116606 0.000105913900703788 -0.00599337263640198"
        rpy="0 0 0" />
      <mass
        value="0.0285277898819827" />
      <inertia
        ixx="6.59852199083716E-06"
        ixy="-6.00722207531335E-11"
        ixz="-1.28572342414589E-10"
        iyy="6.60082070729698E-06"
        iyz="4.18065938760799E-12"
        izz="1.27269366305604E-05" />
    </inertial>
    <visual>
      <origin
        xyz="0 0 0"
        rpy="0 0 0" />
      <geometry>
        <mesh
          filename="package://thubot1_description/meshes/visual/wheel_left_link.STL" />
      </geometry>
      <material
        name="">
        <color
          rgba="0.792156862745098 0.819607843137255 0.933333333333333 1" />
      </material>
    </visual>
    <collision>
      <origin
        xyz="0 0 0"
        rpy="0 0 0" />
      <geometry>
        <mesh
          filename="package://thubot1_description/meshes/collision/wheel_left_link.STL" />
      </geometry>
    </collision>
  </link>
  <joint
    name="wheel_left_joint"
    type="continuous">
    <origin
      xyz="0 0.261 0"
      rpy="-1.5708 0 0" />
    <parent
      link="base_link" />
    <child
      link="wheel_left_link" />
    <axis
      xyz="0 0 1" />
  </joint>
  <link
    name="wheel_right_link">
    <inertial>
      <origin
        xyz="0.000549288231166062 0.000105913900703788 0.00599337263640198"
        rpy="0 0 0" />
      <mass
        value="0.0285277898819827" />
      <inertia
        ixx="6.59852199083716E-06"
        ixy="6.00722207531355E-11"
        ixz="-1.28572342414597E-10"
        iyy="6.60082070729698E-06"
        iyz="-4.18065938760452E-12"
        izz="1.27269366305604E-05" />
    </inertial>
    <visual>
      <origin
        xyz="0 0 0"
        rpy="0 0 0" />
      <geometry>
        <mesh
          filename="package://thubot1_description/meshes/visual/wheel_right_link.STL" />
      </geometry>
      <material
        name="">
        <color
          rgba="0.792156862745098 0.819607843137255 0.933333333333333 1" />
      </material>
    </visual>
    <collision>
      <origin
        xyz="0 0 0"
        rpy="0 0 0" />
      <geometry>
        <mesh
          filename="package://thubot1_description/meshes/collision/wheel_right_link.STL" />
      </geometry>
    </collision>
  </link>
  <joint
    name="wheel_right_joint"
    type="continuous">
    <origin
      xyz="0 -0.261 0"
      rpy="-1.5708 0 0" />
    <parent
      link="base_link" />
    <child
      link="wheel_right_link" />
    <axis
      xyz="0 0 1" />
  </joint> -->

  <link name="iiwa7_link_0">
    <inertial>
      <origin
        xyz="-0.0174205581189087 0.0118841867371313 0.154947000770574" 
        rpy="0 0 0" />
      <mass
        value="2500.467827585255" />
      <inertia
        ixx="6000"
        ixy="-0.00215707368254018"
        ixz="-0.00562783500623309"
        iyy="6000"
        iyz="-0.000208962218248609"
        izz="0.8499070652385" />
    </inertial>
    <!-- 
      ixx="0.379671525908869"
      ixy="-0.00215707368254018"
      ixz="-0.00562783500623309"
      iyy="0.714259639895206"
      iyz="-0.000208962218248609"
      izz="0.8499070652385" />
    -->
    <visual>
      <origin
        xyz="0 0 0"
        rpy="-1.57 0 0" />
      <geometry>
        <mesh
          filename="package://thubot1_description/meshes/visual/base_link.STL" />
      </geometry>
      <material
        name="">
        <color
          rgba="1 1 1 1" />
      </material>
    </visual>
    <collision>
      <origin
        xyz="0.25 -0.25 -0.06"
        rpy="0.0 0 3.1415926" />
      <geometry>
        <mesh
          filename="package://thubot1_description/meshes/collision/base_link_collision.STL" />
      </geometry>
    </collision>
  </link>
  <link name="car_wheel_left_link">
    <inertial>
      <origin
        xyz="-0.00054928823116606 0.000105913900703788 -0.00599337263640198"
        rpy="0 0 0" />
      <mass
        value="0.0285277898819827" />
      <inertia
        ixx="6.59852199083716E-06"
        ixy="-6.00722207531335E-11"
        ixz="-1.28572342414589E-10"
        iyy="6.60082070729698E-06"
        iyz="4.18065938760799E-12"
        izz="1.27269366305604E-05" />
    </inertial>
    <visual>
      <origin
        xyz="0 0 0"
        rpy="-1.57 0 0" />
      <geometry>
        <mesh
          filename="package://thubot1_description/meshes/visual/wheel_left_link.STL" />
      </geometry>
      <material
        name="">
        <color
          rgba="0.792156862745098 0.819607843137255 0.933333333333333 1" />
      </material>
    </visual>
    <collision>
      <origin
        xyz="0 0 0"
        rpy="-1.57 0 0" />
      <geometry>
        <mesh
          filename="package://thubot1_description/meshes/collision/wheel_left_link.STL" />
      </geometry>
    </collision>
  </link>
  <joint name="car_wheel_left_joint" type="continuous">
    <parent link="iiwa7_link_0" />
    <child link="car_wheel_left_link" />
    <origin xyz="0 0.261 0" rpy="-1.5708 0 0" />
    <axis xyz="0 0 1" />
    <limit effort="40" velocity="2"/>
    <dynamics damping="5.5" friction="0.025"/>
  </joint>
  <link name="car_wheel_right_link">
    <inertial>
      <origin
        xyz="0.000549288231166062 0.000105913900703788 0.00599337263640198"
        rpy="0 0 0" />
      <mass
        value="0.0285277898819827" />
      <inertia
        ixx="6.59852199083716E-06"
        ixy="6.00722207531355E-11"
        ixz="-1.28572342414597E-10"
        iyy="6.60082070729698E-06"
        iyz="-4.18065938760452E-12"
        izz="1.27269366305604E-05" />
    </inertial>
    <visual>
      <origin
        xyz="0 0 0"
        rpy="-1.57 0 0" />
      <geometry>
        <mesh
          filename="package://thubot1_description/meshes/visual/wheel_right_link.STL" />
      </geometry>
      <material
        name="">
        <color
          rgba="0.792156862745098 0.819607843137255 0.933333333333333 1" />
      </material>
    </visual>
    <collision>
      <origin
        xyz="0 0 0"
        rpy="-1.57 0 0" />
      <geometry>
        <mesh
          filename="package://thubot1_description/meshes/collision/wheel_right_link.STL" />
      </geometry>
    </collision>
  </link>
  <joint name="car_wheel_right_joint" type="continuous">
    <parent link="iiwa7_link_0" />
    <child link="car_wheel_right_link" />
    <origin
      xyz="0 -0.261 0"
      rpy="-1.5708 0 0" />
    <axis xyz="0 0 1" />
    <limit effort="40" velocity="2"/>
    <dynamics damping="5.5" friction="0.025"/>
  </joint>






  
  <!-- <link
    name="imu_link">
    <inertial>
      <origin
        xyz="0.000792082858284526 1.38777878078145E-17 -0.012670204993692"
        rpy="0 0 1.5708" />
      <mass
        value="0.0468512388980384" />
      <inertia
        ixx="8.11807645296422E-06"
        ixy="-3.95404361424383E-21"
        ixz="-1.02754012116106E-08"
        iyy="1.1732532946275E-05"
        iyz="-4.70553831773323E-21"
        izz="1.50539519804819E-05" />
    </inertial>
    <visual>
      <origin
        xyz="0 0 0"
        rpy="0 0 1.5708" />
      <geometry>
        <mesh
          filename="package://thubot1_description/meshes/visual/imu_link.STL" />
      </geometry>
      <material
        name="">
        <color
          rgba="1 1 1 1" />
      </material>
    </visual>
    <collision>
      <origin
        xyz="0 0 0"
        rpy="0 0 1.5708" />
      <geometry>
        <mesh
          filename="package://thubot1_description/meshes/collision/imu_link.STL" />
      </geometry>
    </collision>
  </link>
  <joint
    name="imu_joint"
    type="fixed">
    <origin
      xyz="-0.132 0.001 0.257"
      rpy="0 0 -1.5708" />
    <parent
      link="base_link" />
    <child
      link="imu_link" />
    <axis
      xyz="0 0 0" />
  </joint>
  <link
    name="base_scan">
    <inertial>
      <origin
        xyz="-0.0792700269732225 -0.000502782516134966 -0.0221945303898931"
        rpy="0 0 3.1415926" />
      <mass
        value="0.000292612751414373" />
      <inertia
        ixx="4.92906410371702E-09"
        ixy="-1.77494869219624E-14"
        ixz="1.01452239690971E-10"
        iyy="2.40304678421701E-09"
        iyz="-2.22399477126053E-15"
        izz="5.79098388231232E-09" />
    </inertial>
    <visual>
      <origin
        xyz="0 0 0"
        rpy="0 0 3.1415926" />
      <geometry>
        <mesh
          filename="package://thubot1_description/meshes/visual/base_scan.STL" />
      </geometry>
      <material
        name="">
        <color
          rgba="0.498039215686275 0.498039215686275 0.498039215686275 1" />
      </material>
    </visual>
    <collision>
      <origin
        xyz="0 0 0"
        rpy="0 0 3.1415926" />
      <geometry>
        <mesh
          filename="package://thubot1_description/meshes/collision/base_scan.STL" />
      </geometry>
    </collision>
  </link>
  <joint
    name="scan_joint"
    type="fixed">
    <origin
      xyz="0.18 0 0.36849"
      rpy="0 0 -3.1415926" />
    <parent
      link="base_link" />
    <child
      link="base_scan" />
    <axis
      xyz="0 0 0" />
  </joint> -->

  <link
    name="shoulder_Link">
    <inertial>
      <origin
        xyz="0.00215579656064623 0.0675269492548249 0.000166380479814213"
        rpy="0 0 0" />
      <mass
        value="2.37326151468102" />
      <inertia
        ixx="0.00464437636424801"
        ixy="3.37752841443834E-06"
        ixz="-6.35167995342536E-06"
        iyy="0.00257740285163467"
        iyz="2.76302522141466E-07"
        izz="0.00472586337172682" />
    </inertial>
    <visual>
      <origin
        xyz="0 0 0"
        rpy="0 0 0" />
      <geometry>
        <mesh
          filename="package://thubot1_description/meshes/visual/shoulder_Link.DAE" />
      </geometry>
      <material
        name="">
        <color
          rgba="0.898039215686275 0.917647058823529 0.929411764705882 1" />
      </material>
    </visual>
    <collision>
      <origin
        xyz="0 0 0"
        rpy="0 0 0" />
      <geometry>
        <mesh
          filename="package://thubot1_description/meshes/collision/shoulder_Link.STL" />
      </geometry>
    </collision>
  </link>
  <joint
    name="j1"
    type="revolute">
    <!-- <origin
      xyz="0 0 0.414"
      rpy="1.5708 0 1.6475096" /> -->
    <origin
      xyz="0 0 0.414"
      rpy="1.5708 0 -3.8503" />
    <!-- <origin
      xyz="0 0 0.074"
      rpy="1.5708 0 0.076717" /> -->
    <parent
      link="iiwa7_link_0" />
    <child
      link="shoulder_Link" />
    <axis
      xyz="0 1 0" />
    <limit
      lower="-3.0543261"
      upper="3.0543261"
      effort="150"
      velocity="3.15" />
    <calibration
      rising="0"
      falling="0" />
    <dynamics
      damping="0"
      friction="0" />
    <safety_controller
      soft_upper_limit="3.0543261"
      soft_lower_limit="-3.0543261"
      k_position="100"
      k_velocity="40" />
  </joint>
  <link
    name="upperarm_Link">
    <inertial>
      <origin
        xyz="0.14052615364316 3.19832122998853E-06 -0.0673220294744213"
        rpy="0 0 0" />
      <mass
        value="5.20488445581566" />
      <inertia
        ixx="0.0100877805389267"
        ixy="-1.86156773781519E-06"
        ixz="7.99549951803734E-16"
        iyy="0.0114295275122961"
        iyz="-4.02196283458795E-16"
        izz="0.0071309461346971" />
    </inertial>
    <visual>
      <origin
        xyz="0 0 0.13"
        rpy="0 0 0" />
      <geometry>
        <mesh
          filename="package://thubot1_description/meshes/visual/upperarm_Link.DAE" />
      </geometry>
      <material
        name="">
        <color
          rgba="0.898039215686275 0.917647058823529 0.929411764705882 1" />
      </material>
    </visual>
    <collision>
      <origin
        xyz="0 0 0"
        rpy="0 0 0" />
      <geometry>
        <mesh
          filename="package://thubot1_description/meshes/collision/upperarm_Link.STL" />
      </geometry>
    </collision>
  </link>
  <joint
    name="j2"
    type="revolute">
    <origin
      xyz="0.048656 0.0652 0.0037401"
      rpy="3.141593 -1.647517 0" /> 
    <parent
      link="shoulder_Link" />
    <child
      link="upperarm_Link" />
    <axis
      xyz="0 0 1" />
    <limit
      lower="-4.6251"
      upper="1.4835"
      effort="150"
      velocity="3.15" />
    <calibration
      rising="0"
      falling="0" />
    <dynamics
      damping="0"
      friction="0" />
    <safety_controller
      soft_upper_limit="1.4835"
      soft_lower_limit="-4.6251"
      k_position="100"
      k_velocity="40" />
  </joint>
  <link
    name="forearm_Link">
    <inertial>
      <origin
        xyz="0.192635357876029 0.0487629311118559 -4.94516124512836E-06"
        rpy="0 0 0" />
      <mass
        value="2.36119902745376" />
      <inertia
        ixx="0.0035452659318639"
        ixy="-7.3938698701374E-05"
        ixz="7.22720216440109E-07"
        iyy="0.00303455488056437"
        iyz="-2.92335000076181E-07"
        izz="0.00417679573122483" />
    </inertial>
    <visual>
      <origin
        xyz="0 0.0025 0"
        rpy="0 0 0" />
      <geometry>
        <mesh
          filename="package://thubot1_description/meshes/visual/forearm_Link.DAE" />
      </geometry>
      <material
        name="">
        <color
          rgba="0.898039215686275 0.917647058823529 0.929411764705882 1" />
      </material>
    </visual>
    <collision>
      <origin
        xyz="0 0 0"
        rpy="0 0 0" />
      <geometry>
        <mesh
          filename="package://thubot1_description/meshes/collision/forearm_Link.STL" />
      </geometry>
    </collision>
  </link>
  <joint
    name="j3"
    type="revolute">
    <origin
      xyz="0.28 0 0"
      rpy="1.5708 0 0" />
    <parent
      link="upperarm_Link" />
    <child
      link="forearm_Link" />
    <axis
      xyz="0 1 0" />
    <limit
      lower="-2.8274"
      upper="2.8274"
      effort="150"
      velocity="3.15" />
    <calibration
      rising="0"
      falling="0" />
    <dynamics
      damping="0"
      friction="0" />
    <safety_controller
      soft_upper_limit="2.8274"
      soft_lower_limit="-2.8274"
      k_position="100"
      k_velocity="40" />
  </joint>
  <link
    name="wrist1_Link">
    <inertial>
      <origin
        xyz="-0.0454134679338634 0.00172297187615156 4.23850043613353E-07"
        rpy="0 0 0" />
      <mass
        value="1.74643097684016" />
      <inertia
        ixx="0.00262730745088668"
        ixy="1.0106539916888E-05"
        ixz="-3.62880005254338E-08"
        iyy="0.00158503705125863"
        iyz="1.43437921244792E-08"
        izz="0.00273363370089196" />
    </inertial>
    <visual>
      <origin
        xyz="0.106 0 0"
        rpy="0 0 0" />
      <geometry>
        <mesh
          filename="package://thubot1_description/meshes/visual/wrist1_Link.DAE" />
      </geometry>
      <material
        name="">
        <color
          rgba="0.898039215686275 0.917647058823529 0.929411764705882 1" />
      </material>
    </visual>
    <collision>
      <origin
        xyz="0 0 0"
        rpy="0 0 0" />
      <geometry>
        <mesh
          filename="package://thubot1_description/meshes/collision/wrist1_Link.STL" />
      </geometry>
    </collision>
  </link>
  <joint
    name="j4"
    type="revolute">
    <origin
      xyz="0.24001 -0.004399 0"
      rpy="1.5708 0 1.5708" />
    <parent
      link="forearm_Link" />
    <child
      link="wrist1_Link" />
    <axis
      xyz="1 0 0" />
    <limit
      lower="-4.6251"
      upper="1.4835"
      effort="28"
      velocity="3.2" />
    <calibration
      rising="0"
      falling="0" />
    <dynamics
      damping="0"
      friction="0" />
    <safety_controller
      soft_upper_limit="1.4835"
      soft_lower_limit="-4.6251"
      k_position="100"
      k_velocity="40" />
  </joint>
  <link
    name="wrist2_Link">
    <inertial>
      <origin
        xyz="-0.0454134586122821 0.00172297186091633 4.35135087973705E-07"
        rpy="0 0 0" />
      <mass
        value="1.74643097580082" />
      <inertia
        ixx="0.00262730745010995"
        ixy="1.01065424165879E-05"
        ixz="-3.62775265607763E-08"
        iyy="0.00158503704914344"
        iyz="1.44762939343378E-08"
        izz="0.00273363369934455" />
    </inertial>
    <visual>
      <origin
        xyz="0 0 0"
        rpy="0 0 0" />
      <geometry>
        <mesh
          filename="package://thubot1_description/meshes/visual/wrist2_Link.DAE" />
      </geometry>
      <material
        name="">
        <color
          rgba="0.898039215686275 0.917647058823529 0.929411764705882 1" />
      </material>
    </visual>
    <collision>
      <origin
        xyz="0 0 0"
        rpy="0 0 0" />
      <geometry>
        <mesh
          filename="package://thubot1_description/meshes/collision/wrist2_Link.STL" />
      </geometry>
    </collision>
  </link>
  <joint
    name="j5"
    type="revolute">
    <origin
      xyz="0.057 -0.15 0"
      rpy="3.141593 0 -1.5708" />
    <parent
      link="wrist1_Link" />
    <child
      link="wrist2_Link" />
    <axis
      xyz="1 0 0" />
    <limit
      lower="-3.0543"
      upper="3.0543"
      effort="28"
      velocity="3.2" />
    <calibration
      rising="0"
      falling="0" />
    <dynamics
      damping="0"
      friction="0" />
    <safety_controller
      soft_upper_limit="3.0543"
      soft_lower_limit="-3.0543"
      k_position="100"
      k_velocity="40" />
  </joint>
  <link
    name="wrist3_Link">
    <inertial>
      <origin
        xyz="-2.38767308875232E-05 0.0229240957730459 7.5877926720147E-05"
        rpy="0 0 0" />
      <mass
        value="1.05057803931133" />
      <inertia
        ixx="0.000555936779063335"
        ixy="5.09768154107326E-07"
        ixz="1.02477772503103E-06"
        iyy="0.000831680492730721"
        iyz="2.52800063915235E-08"
        izz="0.000554791835939161" />
    </inertial>
    <visual>
      <origin
        xyz="0 0 0"
        rpy="0 0 0" />
      <geometry>
        <mesh
          filename="package://thubot1_description/meshes/visual/wrist3_Link.DAE" />
      </geometry>
      <material
        name="">
        <color
          rgba="0.898039215686275 0.917647058823529 0.929411764705882 1" />
      </material>
    </visual>
    <collision>
      <origin
        xyz="0 0 0"
        rpy="0 0 0" />
      <geometry>
        <mesh
          filename="package://thubot1_description/meshes/collision/wrist3_Link.STL" />
      </geometry>
    </collision>
  </link>
  <joint
    name="j6"
    type="revolute">
    <origin
      xyz="-0.048801 -0.0532 0"
      rpy="3.1416 -0.5 0" />
    <parent
      link="wrist2_Link" />
    <child
      link="wrist3_Link" />
    <axis
      xyz="0 1 0" />
    <limit
      lower="-3.0543"
      upper="3.0543"
      effort="28"
      velocity="3.2" />
    <calibration
      rising="0"
      falling="0" />
    <dynamics
      damping="0"
      friction="0" />
    <safety_controller
      soft_upper_limit="3.0543"
      soft_lower_limit="-3.0543"
      k_position="100"
      k_velocity="40" />
  </joint>
  <!-- Removing this joint seems to help with some stability things -->
 
   <link name="part_studio_link">
    <inertial>
      <mass value="0.05"/>
      <origin rpy="0 0 0" xyz="0 0 0"/>
      <inertia ixx="1e-4" ixy="0" ixz="0" iyy="1e-4" iyz="0" izz="1e-4"/>
    </inertial>
    <visual>
      <origin rpy="0 0 0"/> <!--  1.5707 -->
      <geometry>
        <!-- <mesh filename="package://franka_description/meshes/visual/Part Studio 1.obj"/> -->
        <!-- <mesh filename="package://franka_description/meshes/visual/mount_v6.stl" scale="0.001 0.001 0.001"/> -->
        <mesh filename="kuka_allegro_description/meshes/mounts/allegro_mount.obj"/>     
      </geometry>
    </visual>
    <collision>
      <origin rpy="0 0 0"/>
      <geometry>
        <!-- <mesh filename="package://franka_description/meshes/collision/Part Studio 1.obj"/> -->
        <!-- <mesh filename="package://franka_description/meshes/collision/mount_v6.stl" scale="0.001 0.001 0.001"/> -->
        <mesh filename="kuka_allegro_description/meshes/mounts/allegro_mount.obj"/>
      </geometry>
    
        
    </collision>
  </link>

  <joint name="part_studio_joint" type="fixed">
    <!--
    <parent link="panda_link8"/>
    -->
    <parent link="wrist3_Link"/>
    <child link="part_studio_link"/>
    <!-- <origin rpy="0 0 1.571" xyz="-0.02 0.0 0.107"/> -->
    
    <origin rpy="0 0 0" xyz="0 0 0"/>
   
  </joint>

  <!-- <link name="camera_link">
    <inertial>
      <mass value="0.05"/>
      <origin rpy="0 0 0" xyz="0 0 0"/>
      <inertia ixx="1e-4" ixy="0" ixz="0" iyy="1e-4" iyz="0" izz="1e-4"/>
    </inertial>
    <visual>
      <origin rpy="-1.571 0 0"/>
      <geometry>
        <mesh filename="C:\Users\xiaodu\Desktop\urdf_all\franka_panda_allegro/meshes/visual/realsense-d405.stl" scale="0.001 0.001 0.001"/>
      </geometry>
    </visual>
    <collision>
      <origin rpy="-1.571 0 0"/>
      <geometry>
        <mesh filename="C:\Users\xiaodu\Desktop\urdf_all\franka_panda_allegro/meshes/collision/realsense-d405.stl" scale="0.001 0.001 0.001"/>
      </geometry>
    
        
    </collision>
  </link>

  <joint name="camera_joint" type="fixed">
    <parent link="part_studio_link"/>
    <child link="camera_link"/>
    <origin rpy="-0.5 0 3.141592" xyz="-0.03 -0.05 0.055"/>
  </joint> -->

  <joint name="panda_hand_joint" type="fixed">
    <!--
    <parent link="panda_link8"/>
    -->
    <parent link="part_studio_link"/>
    <child link="palm_lower"/>
    <origin rpy="0 3.14 -1.57" xyz="0.05 0.15 0.0"/>
    <!-- <origin rpy="0 0 -0.785398163397" xyz="0 0 0"/> -->
  </joint>

    <link name="palm_lower">
    <inertial>
      <origin xyz="0.0 0.0 0.0" rpy="0.0 0.0 0.0"/>
      <mass value="0.237"/>
      <inertia ixx="0.000354094" ixy="-1.193e-06" ixz="-2.445e-06" iyy="0.000260915" iyz="-2.905e-06" izz="0.000529257"/>
    </inertial>
    <visual>
      <origin xyz="-0.020095249652862544 0.025757756134899473 -0.034722403578460216" rpy="-1.57 -0.0 0.0"/>
      <geometry>
        <mesh filename="../leap_hand/palm_lower.stl"/>
      </geometry>
      <material name="palm_lower_material">
        <color rgba="0.6039215686274509 0.14901960784313725 0.14901960784313725 1.0"/>
      </material>
    </visual>
    <collision>
      <origin xyz="-0.020095249652862544 0.025757756134899473 -0.034722403578460216" rpy="-1.57 -0.0 0.0"/>
      <geometry>
        <mesh filename="../leap_hand/palm_lower.stl"/>
      </geometry>
    </collision>
  </link>
  <link name="mcp_joint">
    <inertial>
      <origin xyz="0.0 0.0 0.0" rpy="0.0 0.0 0.0"/>
      <mass value="0.044"/>
      <inertia ixx="1.1499e-05" ixy="3.049e-06" ixz="1.21e-07" iyy="7.796e-06" iyz="1.12e-07" izz="1.4759e-05"/>
    </inertial>
    <visual>
      <origin xyz="0.008406902261174496 0.0077662438597169954 0.014657354985032912" rpy="-1.5700000000000016 -1.021047330249102e-30 1.7177968783327987e-31"/>
      <geometry>
        <mesh filename="../leap_hand/mcp_joint.stl"/>
      </geometry>
      <material name="mcp_joint_material">
        <color rgba="0.8666666666666667 0.8666666666666667 0.050980392156862744 1.0"/>
      </material>
    </visual>
    <collision>
      <origin xyz="0.008406902261174496 0.0077662438597169954 0.014657354985032912" rpy="-1.5700000000000016 -1.021047330249102e-30 1.7177968783327987e-31"/>
      <geometry>
        <mesh filename="../leap_hand/mcp_joint.stl"/>
      </geometry>
    </collision>
  </link>
  <link name="pip">
    <inertial>
      <origin xyz="0.0 0.0 0.0" rpy="0.0 0.0 0.0"/>
      <mass value="0.032"/>
      <inertia ixx="4.798e-06" ixy="1.2e-08" ixz="4e-09" iyy="2.862e-06" iyz="1.1e-08" izz="4.234e-06"/>
    </inertial>
    <visual>
      <origin xyz="0.009643363092271328 0.0002999999999999895 0.0007840340104173765" rpy="0.0007963267948964958 -1.5707963267948963 0.0"/>
      <geometry>
        <mesh filename="../leap_hand/pip.stl"/>
      </geometry>
      <material name="pip_material">
        <color rgba="0.7490196078431373 0.7490196078431373 0.7490196078431373 1.0"/>
      </material>
    </visual>
    <collision>
      <origin xyz="0.009643363092271328 0.0002999999999999895 0.0007840340104173765" rpy="0.0007963267948964958 -1.5707963267948963 0.0"/>
      <geometry>
        <mesh filename="../leap_hand/pip.stl"/>
      </geometry>
    </collision>
  </link>
  <link name="dip">
    <inertial>
      <origin xyz="0.0 0.0 0.0" rpy="0.0 0.0 0.0"/>
      <mass value="0.037"/>
      <inertia ixx="5.542e-06" ixy="-6.07e-07" ixz="-1.7e-08" iyy="5.727e-06" iyz="-2.3e-08" izz="6.682e-06"/>
    </inertial>
    <visual>
      <origin xyz="0.021133352895225003 -0.00843211914670488 0.00978508816209524" rpy="1.571592653589793 4.507511124216441e-32 4.439548105392361e-32"/>
      <geometry>
        <mesh filename="../leap_hand/dip.stl"/>
      </geometry>
      <material name="dip_material">
        <color rgba="0.8666666666666667 0.8666666666666667 0.050980392156862744 1.0"/>
      </material>
    </visual>
    <collision>
      <origin xyz="0.021133352895225003 -0.00843211914670488 0.00978508816209524" rpy="1.571592653589793 4.507511124216441e-32 4.439548105392361e-32"/>
      <geometry>
        <mesh filename="../leap_hand/dip.stl"/>
      </geometry>
    </collision>
  </link>
  <link name="fingertip">
    <inertial>
      <origin xyz="0.0 0.0 0.0" rpy="0.0 0.0 0.0"/>
      <mass value="0.016"/>
      <inertia ixx="3.368e-06" ixy="1.15e-07" ixz="0.0" iyy="1.556e-06" iyz="0.0" izz="2.863e-06"/>
    </inertial>
    <visual>
      <origin xyz="0.013286424108533503 -0.006114238386541987 0.014499999999999498" rpy="-4.711592653589793 1.1993117970061735e-33 4.439548105392361e-32"/>
      <geometry>
        <mesh filename="../leap_hand/fingertip.stl"/>
      </geometry>
      <material name="fingertip_material">
        <color rgba="0.8666666666666667 0.8666666666666667 0.050980392156862744 1.0"/>
      </material>
    </visual>
    <collision>
      <origin xyz="0.013286424108533503 -0.006114238386541987 0.014499999999999498" rpy="-4.711592653589793 1.1993117970061735e-33 4.439548105392361e-32"/>
      <geometry>
        <mesh filename="../leap_hand/fingertip.stl"/>
      </geometry>
    </collision>
  </link>
  <joint name="0" type="revolute">
    <origin xyz="-0.012200000000000008 0.038099999999999995 0.0145" rpy="-1.5707963267948966 -1.0065212660796337e-15 1.5707963267948943"/>
    <axis xyz="0.0 0.0 -1.0"/>
    <parent link="mcp_joint"/>
    <child link="pip"/>
    <limit effort="0.95" lower="-1.047" upper="1.047" velocity="8.48"/>
  </joint>
  <joint name="1" type="revolute">
    <origin xyz="-0.007095249652862546 0.023057756134899472 -0.01872240357846022" rpy="1.570796326794895 1.5707963267948946 0.0"/>
    <axis xyz="0.0 0.0 -1.0"/>
    <parent link="palm_lower"/>
    <child link="mcp_joint"/>
    <limit effort="0.95" lower="-0.314" upper="2.23" velocity="8.48"/>
  </joint>
  <joint name="2" type="revolute">
    <origin xyz="0.014999999999999968 0.014299999999999905 -0.012999999999999824" rpy="1.570796326794896 -1.5707963267948963 0.0"/>
    <axis xyz="0.0 0.0 -1.0"/>
    <parent link="pip"/>
    <child link="dip"/>
    <limit effort="0.95" lower="-0.506" upper="1.885" velocity="8.48"/>
  </joint>
  <joint name="3" type="revolute">
    <origin xyz="-4.088058249557269e-09 -0.03610000421036737 0.0002000000000000786" rpy="4.5935029425113685e-17 -2.8730071914463795e-16 4.439548105392361e-32"/>
    <axis xyz="0.0 0.0 -1.0"/>
    <parent link="dip"/>
    <child link="fingertip"/>
    <limit effort="0.95" lower="-0.366" upper="2.042" velocity="8.48"/>
  </joint>
  <link name="mcp_joint_2">
    <inertial>
      <origin xyz="0.0 0.0 0.0" rpy="0.0 0.0 0.0"/>
      <mass value="0.044"/>
      <inertia ixx="1.1499e-05" ixy="3.049e-06" ixz="1.21e-07" iyy="7.796e-06" iyz="1.12e-07" izz="1.4759e-05"/>
    </inertial>
    <visual>
      <origin xyz="0.008406902261174496 0.0077662438597169954 0.014657354985032914" rpy="-1.5700000000000016 -1.0076465469034e-30 2.1209300131419907e-61"/>
      <geometry>
        <mesh filename="../leap_hand/mcp_joint.stl"/>
      </geometry>
      <material name="mcp_joint_material">
        <color rgba="0.8666666666666667 0.8666666666666667 0.050980392156862744 1.0"/>
      </material>
    </visual>
    <collision>
      <origin xyz="0.008406902261174496 0.0077662438597169954 0.014657354985032914" rpy="-1.5700000000000016 -1.0076465469034e-30 2.1209300131419907e-61"/>
      <geometry>
        <mesh filename="../leap_hand/mcp_joint.stl"/>
      </geometry>
    </collision>
  </link>
  <link name="pip_2">
    <inertial>
      <origin xyz="0.0 0.0 0.0" rpy="0.0 0.0 0.0"/>
      <mass value="0.032"/>
      <inertia ixx="4.798e-06" ixy="1.2e-08" ixz="4e-09" iyy="2.862e-06" iyz="1.1e-08" izz="4.234e-06"/>
    </inertial>
    <visual>
      <origin xyz="0.009643363092271328 0.0002999999999999947 0.0007840340104173765" rpy="0.0007963267948964958 -1.5707963267948963 0.0"/>
      <geometry>
        <mesh filename="../leap_hand/pip.stl"/>
      </geometry>
      <material name="pip_material">
        <color rgba="0.7490196078431373 0.7490196078431373 0.7490196078431373 1.0"/>
      </material>
    </visual>
    <collision>
      <origin xyz="0.009643363092271328 0.0002999999999999947 0.0007840340104173765" rpy="0.0007963267948964958 -1.5707963267948963 0.0"/>
      <geometry>
        <mesh filename="../leap_hand/pip.stl"/>
      </geometry>
    </collision>
  </link>
  <link name="dip_2">
    <inertial>
      <origin xyz="0.0 0.0 0.0" rpy="0.0 0.0 0.0"/>
      <mass value="0.037"/>
      <inertia ixx="5.542e-06" ixy="-6.07e-07" ixz="-1.7e-08" iyy="5.727e-06" iyz="-2.3e-08" izz="6.682e-06"/>
    </inertial>
    <visual>
      <origin xyz="0.021133352895225003 -0.008432119146704865 0.009785088162095237" rpy="1.571592653589793 2.1146933785271956e-32 1.4408183216511869e-31"/>
      <geometry>
        <mesh filename="../leap_hand/dip.stl"/>
      </geometry>
      <material name="dip_material">
        <color rgba="0.8666666666666667 0.8666666666666667 0.050980392156862744 1.0"/>
      </material>
    </visual>
    <collision>
      <origin xyz="0.021133352895225003 -0.008432119146704865 0.009785088162095237" rpy="1.571592653589793 2.1146933785271956e-32 1.4408183216511869e-31"/>
      <geometry>
        <mesh filename="../leap_hand/dip.stl"/>
      </geometry>
    </collision>
  </link>
  <link name="fingertip_2">
    <inertial>
      <origin xyz="0.0 0.0 0.0" rpy="0.0 0.0 0.0"/>
      <mass value="0.016"/>
      <inertia ixx="3.368e-06" ixy="1.15e-07" ixz="0.0" iyy="1.556e-06" iyz="0.0" izz="2.863e-06"/>
    </inertial>
    <visual>
      <origin xyz="0.013286424108533496 -0.006114238386542001 0.014499999999999496" rpy="-4.711592653589793 -4.317959788283594e-33 1.4408183216511869e-31"/>
      <geometry>
        <mesh filename="../leap_hand/fingertip.stl"/>
      </geometry>
      <material name="fingertip_material">
        <color rgba="0.8666666666666667 0.8666666666666667 0.050980392156862744 1.0"/>
      </material>
    </visual>
    <collision>
      <origin xyz="0.013286424108533496 -0.006114238386542001 0.014499999999999496" rpy="-4.711592653589793 -4.317959788283594e-33 1.4408183216511869e-31"/>
      <geometry>
        <mesh filename="../leap_hand/fingertip.stl"/>
      </geometry>
    </collision>
  </link>
  <joint name="4" type="revolute">
    <origin xyz="-0.01220000000000002 0.03809999999999998 0.014500000000000006" rpy="-1.5707963267948966 -1.006521276005794e-15 1.5707963267948943"/>
    <axis xyz="0.0 0.0 -1.0"/>
    <parent link="mcp_joint_2"/>
    <child link="pip_2"/>
    <limit effort="0.95" lower="-1.047" upper="1.047" velocity="8.48"/>
  </joint>
  <joint name="5" type="revolute">
    <origin xyz="-0.007095249652862539 -0.022392243865100525 -0.01872240357846023" rpy="1.5707963267948966 1.5707963267948966 0.0"/>
    <axis xyz="0.0 0.0 -1.0"/>
    <parent link="palm_lower"/>
    <child link="mcp_joint_2"/>
    <limit effort="0.95" lower="-0.314" upper="2.23" velocity="8.48"/>
  </joint>
  <joint name="6" type="revolute">
    <origin xyz="0.014999999999999975 0.0143 -0.013000000000000018" rpy="1.570796326794896 -1.5707963267948963 0.0"/>
    <axis xyz="0.0 0.0 -1.0"/>
    <parent link="pip_2"/>
    <child link="dip_2"/>
    <limit effort="0.95" lower="-0.506" upper="1.885" velocity="8.48"/>
  </joint>
  <joint name="7" type="revolute">
    <origin xyz="1.0061396160665481e-16 -0.036099999999999854 0.0002000000000000786" rpy="4.5935029425113654e-17 -2.8730071914463795e-16 1.4408183216511869e-31"/>
    <axis xyz="0.0 0.0 -1.0"/>
    <parent link="dip_2"/>
    <child link="fingertip_2"/>
    <limit effort="0.95" lower="-0.366" upper="2.042" velocity="8.48"/>
  </joint>
  <link name="mcp_joint_3">
    <inertial>
      <origin xyz="0.0 0.0 0.0" rpy="0.0 0.0 0.0"/>
      <mass value="0.044"/>
      <inertia ixx="1.1499e-05" ixy="3.049e-06" ixz="1.21e-07" iyy="7.796e-06" iyz="1.12e-07" izz="1.4759e-05"/>
    </inertial>
    <visual>
      <origin xyz="0.0084069022611745 0.007766243859716996 0.014657354985032914" rpy="-1.5700000000000016 -1.0059504988632627e-30 5.729641584552035e-32"/>
      <geometry>
        <mesh filename="../leap_hand/mcp_joint.stl"/>
      </geometry>
      <material name="mcp_joint_material">
        <color rgba="0.8666666666666667 0.8666666666666667 0.050980392156862744 1.0"/>
      </material>
    </visual>
    <collision>
      <origin xyz="0.0084069022611745 0.007766243859716996 0.014657354985032914" rpy="-1.5700000000000016 -1.0059504988632627e-30 5.729641584552035e-32"/>
      <geometry>
        <mesh filename="../leap_hand/mcp_joint.stl"/>
      </geometry>
    </collision>
  </link>
  <link name="pip_3">
    <inertial>
      <origin xyz="0.0 0.0 0.0" rpy="0.0 0.0 0.0"/>
      <mass value="0.032"/>
      <inertia ixx="4.798e-06" ixy="1.2e-08" ixz="4e-09" iyy="2.862e-06" iyz="1.1e-08" izz="4.234e-06"/>
    </inertial>
    <visual>
      <origin xyz="0.009643363092271331 0.00029999999999998084 0.0007840340104173765" rpy="0.0007963267948964958 -1.5707963267948963 0.0"/>
      <geometry>
        <mesh filename="../leap_hand/pip.stl"/>
      </geometry>
      <material name="pip_material">
        <color rgba="0.7490196078431373 0.7490196078431373 0.7490196078431373 1.0"/>
      </material>
    </visual>
    <collision>
      <origin xyz="0.009643363092271331 0.00029999999999998084 0.0007840340104173765" rpy="0.0007963267948964958 -1.5707963267948963 0.0"/>
      <geometry>
        <mesh filename="../leap_hand/pip.stl"/>
      </geometry>
    </collision>
  </link>
  <link name="dip_3">
    <inertial>
      <origin xyz="0.0 0.0 0.0" rpy="0.0 0.0 0.0"/>
      <mass value="0.037"/>
      <inertia ixx="5.542e-06" ixy="-6.07e-07" ixz="-1.7e-08" iyy="5.727e-06" iyz="-2.3e-08" izz="6.682e-06"/>
    </inertial>
    <visual>
      <origin xyz="0.021133352895225006 -0.008432119146704865 0.009785088162095237" rpy="1.571592653589793 -1.4095651113919093e-33 1.5565411607615035e-32"/>
      <geometry>
        <mesh filename="../leap_hand/dip.stl"/>
      </geometry>
      <material name="dip_material">
        <color rgba="0.8666666666666667 0.8666666666666667 0.050980392156862744 1.0"/>
      </material>
    </visual>
    <collision>
      <origin xyz="0.021133352895225006 -0.008432119146704865 0.009785088162095237" rpy="1.571592653589793 -1.4095651113919093e-33 1.5565411607615035e-32"/>
      <geometry>
        <mesh filename="../leap_hand/dip.stl"/>
      </geometry>
    </collision>
  </link>
  <link name="fingertip_3">
    <inertial>
      <origin xyz="0.0 0.0 0.0" rpy="0.0 0.0 0.0"/>
      <mass value="0.016"/>
      <inertia ixx="3.368e-06" ixy="1.15e-07" ixz="0.0" iyy="1.556e-06" iyz="0.0" izz="2.863e-06"/>
    </inertial>
    <visual>
      <origin xyz="0.013286424108533501 -0.006114238386541987 0.0144999999999995" rpy="-4.711592653589793 8.61707169505754e-33 1.5565411607615035e-32"/>
      <geometry>
        <mesh filename="../leap_hand/fingertip.stl"/>
      </geometry>
      <material name="fingertip_material">
        <color rgba="0.8666666666666667 0.8666666666666667 0.050980392156862744 1.0"/>
      </material>
    </visual>
    <collision>
      <origin xyz="0.013286424108533501 -0.006114238386541987 0.0144999999999995" rpy="-4.711592653589793 8.61707169505754e-33 1.5565411607615035e-32"/>
      <geometry>
        <mesh filename="../leap_hand/fingertip.stl"/>
      </geometry>
    </collision>
  </link>
  <joint name="8" type="revolute">
    <origin xyz="-0.012200000000000004 0.0381 0.014499999999999999" rpy="-1.5707963267948966 -1.006521266079636e-15 1.5707963267948943"/>
    <axis xyz="0.0 0.0 -1.0"/>
    <parent link="mcp_joint_3"/>
    <child link="pip_3"/>
    <limit effort="0.95" lower="-1.047" upper="1.047" velocity="8.48"/>
  </joint>
  <joint name="9" type="revolute">
    <origin xyz="-0.007095245442639837 -0.06784224386510052 -0.018722407666402933" rpy="1.570796326794895 1.5707963267948946 0.0"/>
    <axis xyz="0.0 0.0 -1.0"/>
    <parent link="palm_lower"/>
    <child link="mcp_joint_3"/>
    <limit effort="0.95" lower="-0.314" upper="2.23" velocity="8.48"/>
  </joint>
  <joint name="10" type="revolute">
    <origin xyz="0.014999999999999972 0.014299999999999952 -0.01299999999999996" rpy="1.570796326794896 -1.5707963267948963 0.0"/>
    <axis xyz="0.0 0.0 -1.0"/>
    <parent link="pip_3"/>
    <child link="dip_3"/>
    <limit effort="0.95" lower="-0.506" upper="1.885" velocity="8.48"/>
  </joint>
  <joint name="11" type="revolute">
    <origin xyz="9.71445146547012e-17 -0.03609999999999987 0.00020000000000007512" rpy="4.5935029425113685e-17 -2.87300719144638e-16 1.5565411607615035e-32"/>
    <axis xyz="0.0 0.0 -1.0"/>
    <parent link="dip_3"/>
    <child link="fingertip_3"/>
    <limit effort="0.95" lower="-0.366" upper="2.042" velocity="8.48"/>
  </joint>
  <link name="pip_4">
    <inertial>
      <origin xyz="0.0 0.0 0.0" rpy="0.0 0.0 0.0"/>
      <mass value="0.032"/>
      <inertia ixx="4.798e-06" ixy="1.2e-08" ixz="4e-09" iyy="2.862e-06" iyz="1.1e-08" izz="4.234e-06"/>
    </inertial>
    <visual>
      <origin xyz="-0.005356636907728671 0.0002999999999999999 0.0007840340104173782" rpy="0.0007963267948964958 -1.5707963267948963 0.0"/>
      <geometry>
        <mesh filename="../leap_hand/pip.stl"/>
      </geometry>
      <material name="pip_material">
        <color rgba="0.7490196078431373 0.7490196078431373 0.7490196078431373 1.0"/>
      </material>
    </visual>
    <collision>
      <origin xyz="-0.005356636907728671 0.0002999999999999999 0.0007840340104173782" rpy="0.0007963267948964958 -1.5707963267948963 0.0"/>
      <geometry>
        <mesh filename="../leap_hand/pip.stl"/>
      </geometry>
    </collision>
  </link>
  <link name="thumb_pip">
    <inertial>
      <origin xyz="0.0 0.0 0.0" rpy="0.0 0.0 0.0"/>
      <mass value="0.003"/>
      <inertia ixx="5.93e-07" ixy="0.0" ixz="0.0" iyy="5.49e-07" iyz="0.0" izz="2.24e-07"/>
    </inertial>
    <visual>
      <origin xyz="0.011961920770611187 -5.30825383648903e-16 -0.0158526489566642" rpy="-3.140796326794897 1.6050198443300153e-46 -3.9204996250525193e-59"/>
      <geometry>
        <mesh filename="../leap_hand/thumb_pip.stl"/>
      </geometry>
      <material name="thumb_pip_material">
        <color rgba="0.8666666666666667 0.8666666666666667 0.050980392156862744 1.0"/>
      </material>
    </visual>
    <collision>
      <origin xyz="0.011961920770611187 -5.30825383648903e-16 -0.0158526489566642" rpy="-3.140796326794897 1.6050198443300153e-46 -3.9204996250525193e-59"/>
      <geometry>
        <mesh filename="../leap_hand/thumb_pip.stl"/>
      </geometry>
    </collision>
  </link>
  <link name="thumb_dip">
    <inertial>
      <origin xyz="0.0 0.0 0.0" rpy="0.0 0.0 0.0"/>
      <mass value="0.038"/>
      <inertia ixx="8.474e-06" ixy="2.41e-07" ixz="2.6e-08" iyy="3.841e-06" iyz="2.5e-08" izz="7.679e-06"/>
    </inertial>
    <visual>
      <origin xyz="0.043968715707239175 0.0579529529737092 -0.008628676449369476" rpy="-1.5700000000000003 3.27515792264422e-15 1.112375852965736e-46"/>
      <geometry>
        <mesh filename="../leap_hand/thumb_dip.stl"/>
      </geometry>
      <material name="thumb_dip_material">
        <color rgba="0.8666666666666667 0.8666666666666667 0.050980392156862744 1.0"/>
      </material>
    </visual>
    <collision>
      <origin xyz="0.043968715707239175 0.0579529529737092 -0.008628676449369476" rpy="-1.5700000000000003 3.27515792264422e-15 1.112375852965736e-46"/>
      <geometry>
        <mesh filename="../leap_hand/thumb_dip.stl"/>
      </geometry>
    </collision>
  </link>
  <link name="thumb_fingertip">
    <inertial>
      <origin xyz="0.0 0.0 0.0" rpy="0.0 0.0 0.0"/>
      <mass value="0.049"/>
      <inertia ixx="2.0372e-05" ixy="-4.89e-07" ixz="-3e-08" iyy="4.336e-06" iyz="-9.7e-08" izz="1.9845e-05"/>
    </inertial>
    <visual>
      <origin xyz="0.06255953846266739 0.07845968291139699 0.048992911807332215" rpy="-1.57 -3.33066907387547e-16 1.2042408677791935e-46"/>
      <geometry>
        <mesh filename="../leap_hand/thumb_fingertip.stl"/>
      </geometry>
      <material name="thumb_fingertip_material">
        <color rgba="0.6039215686274509 0.14901960784313725 0.14901960784313725 1.0"/>
      </material>
    </visual>
    <collision>
      <origin xyz="0.06255953846266739 0.07845968291139699 0.048992911807332215" rpy="-1.57 -3.33066907387547e-16 1.2042408677791935e-46"/>
      <geometry>
        <mesh filename="../leap_hand/thumb_fingertip.stl"/>
      </geometry>
    </collision>
  </link>
  <joint name="12" type="revolute">
    <origin xyz="-0.06939524965286253 -0.0012422438651005258 -0.021622403578460216" rpy="-8.238176646493942e-17 1.5707963267948957 0.0"/>
    <axis xyz="0.0 0.0 -1.0"/>
    <parent link="palm_lower"/>
    <child link="pip_4"/>
    <limit effort="0.95" lower="-0.349" upper="2.094" velocity="8.48"/>
  </joint>
  <joint name="13" type="revolute">
    <origin xyz="-2.7755575615628914e-17 0.014300000000000005 -0.013000000000000012" rpy="1.570796326794896 -1.5707963267948963 0.0"/>
    <axis xyz="0.0 0.0 -1.0"/>
    <parent link="pip_4"/>
    <child link="thumb_pip"/>
    <limit effort="0.95" lower="-0.47" upper="2.443" velocity="8.48"/>
  </joint>
  <joint name="14" type="revolute">
    <origin xyz="0.0 0.014499999999999966 -0.017000000000000053" rpy="-1.5707963267948966 1.6050198443300131e-46 -1.9721522630516625e-31"/>
    <axis xyz="0.0 0.0 -1.0"/>
    <parent link="thumb_pip"/>
    <child link="thumb_dip"/>
    <limit effort="0.95" lower="-1.2" upper="1.9" velocity="8.48"/>
  </joint>
  <joint name="15" type="revolute">
    <origin xyz="-1.249000902703301e-16 0.046599999999999864 0.0001999999999999771" rpy="1.506395849149178e-44 5.423418723393526e-31 3.141592653589793"/>
    <axis xyz="0.0 0.0 -1.0"/>
    <parent link="thumb_dip"/>
    <child link="thumb_fingertip"/>
    <limit effort="0.95" lower="-1.34" upper="1.88" velocity="8.48"/>
  </joint>


</robot>

